Workbook

Sheet jira_full_export
A1: Issue Key | B1: Issue Type | C1: Summary | D1: Description | E1: Status | F1: Priority | G1: Resolution | H1: Created | I1: Updated | J1: Resolved | K1: Component/s | L1: Affects Version/s | M1: Fix Version/s | N1: Reporter | O1: Assignee | P1: Votes | Q1: Watchers | R1: Original Estimate | S1: Remaining Estimate | T1: Time Spent | U1: Work Ratio | V1: Аудитория | W1: Группа A/B теста | X1: Категория проблемы | Y1: Кафедра | Z1: Влияние на процесс | AA1: Источник заявки | AB1: Время решения (часы) | AC1: Комментарии | AD1: Labels | AE1: Environment | AF1: Linked Issues | AG1: Created Date | AH1: Resolved Date | AI1: Due Date | AJ1: Количество повторов | AK1: Сложность решения | AL1: Тип вмешательства
A2: MMC-1004 | B2: Инцидент | C2: Не могу включить проектор в аудитории Гл-108 | D2: ЗАЯВКА В ТЕХПОДДЕРЖКУ 1. Общие сведения: - Аудитория: Гл-108 - Преподаватель: Волков Б.Б. - Подразделение: Кафедра безопасности информационных систем - Дата/время: 17.03.2024 17:27 2. Суть проблемы: Не могу включить проектор 3. Симптомы: Система зависает при определенных действиях 4. Влияние на учебный процесс: Проведено с ограничениями Контакт для обратной связи: Волков Б.Б. | E2: Решена | F2: Low | G2: Решено | H2: 45931.416 | I2: 45932.26 | J2: 45932.26 | K2: Другое оборудование | L2: MMC v2.7 | M2: MMC v4.1 | N2: Волков Б.Б. | P2: 0 | Q2: support_team | T2: 5h | U2: 217 | V2: Гл-108 | W2: A | X2: Не могу включить проектор | Y2: Кафедра безопасности информационных систем | Z2: Высокое | AA2: Телефон | AB2: 20.2 | AD2: software | AE2: Windows 7 / Intel CPU | AG2: 45931.416 | AH2: 45932.26 | AJ2: 2 | AK2: Низкая | AL2: Консультация
A3: MMC-1097 | B3: Инцидент | C3: Неисправность оборудования в Гл-210: Не могу включить проектор | D3: СООБЩЕНИЕ О ПРОБЛЕМЕ ------------------ Аудитория: Гл-210 Оборудование: Мультимедийный комплекс Преподаватель: Кузнецов А.А. Кафедра: Кафедра иностранных языков ПРОБЛЕМА: Не могу включить проектор ВРЕМЯ ВОЗНИКНОВЕНИЯ: 25.03.2024 15:43 ДОПОЛНИТЕЛЬНАЯ ИНФОРМАЦИЯ: Проблема возникает при каждом использовании СТАТУС: Требуется вмешательство специалиста | E3: Решена | F3: Medium | G3: Решено | H3: 45931.508 | I3: 45931.824 | J3: 45931.824 | K3: Сетевое оборудование | L3: MMC v3.3 | M3: MMC v2.5 | N3: Кузнецов А.А. | O3: Смирнова О.Л. | P3: 0 | Q3: multimedia_dept | R3: 2h | T3: 3h | U3: 147 | V3: Гл-210 | W3: B | X3: Не могу включить проектор | Y3: Кафедра иностранных языков | Z3: Низкое | AA3: Портал самообслуживания | AB3: 7.6 | AD3: equipment | AE3: Windows 10 / AMD CPU | AG3: 45931.508 | AH3: 45931.824 | AI3: 45934 | AJ3: 1 | AK3: Высокая | AL3: Консультация
A4: MMC-1033 | B4: Инцидент | C4: Нет изображения на экране в аудитории Гл-115 | D4: СООБЩЕНИЕ О ПРОБЛЕМЕ ------------------ Аудитория: Гл-115 Оборудование: Мультимедийный комплекс Преподаватель: Иванов В.В. Кафедра: Кафедра иностранных языков ПРОБЛЕМА: Нет изображения на экране ВРЕМЯ ВОЗНИКНОВЕНИЯ: 15.03.2024 17:00 ДОПОЛНИТЕЛЬНАЯ ИНФОРМАЦИЯ: Проблема возникает при каждом использовании СТАТУС: Требуется вмешательство специалиста | E4: Решена | F4: Low | G4: Решено | H4: 45931.585 | I4: 45932.596 | J4: 45932.596 | K4: ПО | L4: MMC v3.9 | M4: MMC v4.1 | N4: Иванов В.В. | O4: Кузнецова Е.П. | P4: 2 | T4: 4h | U4: 427 | V4: Гл-115 | W4: A | X4: Нет изображения на экране | Y4: Кафедра иностранных языков | Z4: Низкое | AA4: Телефон | AB4: 24.2 | AD4: training_needed | AE4: Windows 11 / Intel CPU | AG4: 45931.585 | AH4: 45932.596 | AJ4: 1 | AK4: Средняя | AL4: На месте
A5: MMC-1091 | B5: Проблема | C5: Неисправность оборудования в Гл-211: Другая проблема | D5: СООБЩЕНИЕ О ПРОБЛЕМЕ ------------------ Аудитория: Гл-211 Оборудование: Мультимедийный комплекс Преподаватель: Смирнов В.В. Кафедра: Кафедра инженерной графики ПРОБЛЕМА: Другая проблема ВРЕМЯ ВОЗНИКНОВЕНИЯ: 17.03.2024 09:25 ДОПОЛНИТЕЛЬНАЯ ИНФОРМАЦИЯ: Проблема возникает при каждом использовании СТАТУС: Требуется вмешательство специалиста | E5: Решена | F5: Medium | G5: Решено | H5: 45931.734 | I5: 45933.326 | J5: 45933.326 | K5: Акустика | L5: MMC v2.2 | M5: MMC v2.9 | N5: Смирнов В.В. | O5: Сидоров Д.К. | P5: 3 | Q5: support_team | T5: 4h | U5: 218 | V5: Гл-211 | W5: B | X5: Другая проблема | Y5: Кафедра инженерной графики | Z5: Критичное | AA5: Портал самообслуживания | AB5: 38.2 | AD5: multimedia | AE5: Windows 8 / AMD CPU | AG5: 45931.734 | AH5: 45933.326 | AI5: 45932 | AJ5: 0 | AK5: Высокая | AL5: На месте
A6: MMC-1074 | B6: Запрос на обслуживание | C6: Аудитория Гл-208: Сложность с настройкой источников | D6: ЗАЯВКА В ТЕХПОДДЕРЖКУ 1. Общие сведения: - Аудитория: Гл-208 - Преподаватель: Васильев А.А. - Подразделение: Кафедра информатики и вычислительной техники - Дата/время: 09.03.2024 15:54 2. Суть проблемы: Сложность с настройкой источников 3. Симптомы: Изображение/звук появляются и пропадают 4. Влияние на учебный процесс: Перенесено в другую аудиторию Контакт для обратной связи: Васильев А.А. | E6: Решена | F6: Low | G6: Решено | H6: 45932.428 | I6: 45934.122 | J6: 45934.122 | K6: Сетевое оборудование | L6: MMC v2.4 | M6: MMC v4.9 | N6: Васильев А.А. | O6: Кузнецова Е.П. | P6: 3 | R6: 4h | T6: 6h | U6: 348 | V6: Гл-208 | W6: B | X6: Сложность с настройкой источников | Y6: Кафедра информатики и вычислительной техники | Z6: Среднее | AA6: Телефон | AB6: 40.6 | AC6: Проблема в драйверах. Обновлено программное обеспечение. | AD6: multimedia | AE6: Windows 9 / AMD CPU | AG6: 45932.428 | AH6: 45934.122 | AI6: 45937 | AJ6: 0 | AK6: Низкая | AL6: Удаленно
A7: MMC-1025 | B7: Проблема | C7: Неисправность оборудования в Гл-105: Не могу включить проектор | D7: Преподаватель: Васильев В.В. Подразделение: Кафедра иностранных языков Аудитория: Гл-105 Дата возникновения проблемы: 02.03.2024 15:54 Описание проблемы: Не могу включить проектор Предпринятые действия: Проверил настройки ПО, проблема не решена Контактный телефон: +7 (978) 390-84-70 | E7: Решена | F7: Medium | G7: Решено | H7: 45932.449 | I7: 45932.815 | J7: 45932.815 | K7: Сетевое оборудование | L7: MMC v1.1 | M7: MMC v3.9 | N7: Васильев В.В. | P7: 1 | Q7: support_team | T7: 5h | U7: 380 | V7: Гл-105 | W7: A | X7: Не могу включить проектор | Y7: Кафедра иностранных языков | Z7: Среднее | AA7: Личное обращение | AB7: 8.8 | AC7: Требуется замена блока питания. Оборудование снято с эксплуатации. | AD7: urgent | AE7: Windows 10 / AMD CPU | AG7: 45932.449 | AH7: 45932.815 | AI7: 45939 | AJ7: 1 | AK7: Средняя | AL7: На месте
A8: MMC-1035 | B8: Запрос на обслуживание | C8: Не подключается ноутбук через HDMI. Аудитория: Гл-105 | D8: СООБЩЕНИЕ О ПРОБЛЕМЕ ------------------ Аудитория: Гл-105 Оборудование: Мультимедийный комплекс Преподаватель: Сидоров В.В. Кафедра: Кафедра высшей математики ПРОБЛЕМА: Не подключается ноутбук через HDMI ВРЕМЯ ВОЗНИКНОВЕНИЯ: 26.03.2024 09:46 ДОПОЛНИТЕЛЬНАЯ ИНФОРМАЦИЯ: Проблема возникает при каждом использовании СТАТУС: Требуется вмешательство специалиста | E8: Решена | F8: Medium | G8: Решено | H8: 45932.758 | I8: 45932.963 | J8: 45932.963 | K8: Компьютер | L8: MMC v1.1 | M8: MMC v3.4 | N8: Сидоров В.В. | P8: 3 | T8: 3h | U8: 328 | V8: Гл-105 | W8: A | X8: Не подключается ноутбук через HDMI | Y8: Кафедра высшей математики | Z8: Критичное | AA8: Портал самообслуживания | AB8: 4.9 | AC8: Проведена диагностика. Оборудование работает в штатном режиме. | AD8: urgent | AE8: Windows 7 / Intel CPU | AG8: 45932.758 | AH8: 45932.963 | AJ8: 1 | AK8: Низкая | AL8: Удаленно
A9: MMC-1002 | B9: Инцидент | C9: Другая проблема. Аудитория: Гл-112 | D9: СООБЩЕНИЕ О ПРОБЛЕМЕ ------------------ Аудитория: Гл-112 Оборудование: Мультимедийный комплекс Преподаватель: Волков А.А. Кафедра: Кафедра органической химии ПРОБЛЕМА: Другая проблема ВРЕМЯ ВОЗНИКНОВЕНИЯ: 21.03.2024 10:34 ДОПОЛНИТЕЛЬНАЯ ИНФОРМАЦИЯ: Иногда работает нормально, иногда нет СТАТУС: Требуется вмешательство специалиста | E9: В работе | F9: Medium | H9: 45933.363 | I9: 45934.946 | K9: Другое оборудование | L9: MMC v3.8 | N9: Волков А.А. | P9: 2 | V9: Гл-112 | W9: A | X9: Другая проблема | Y9: Кафедра органической химии | Z9: Критичное | AA9: Портал самообслуживания | AD9: multimedia | AE9: Windows 8 / AMD CPU | AG9: 45933.363 | AJ9: 3 | AK9: Низкая | AL9: На месте
A10: MMC-1072 | B10: Инцидент | C10: Аудитория Гл-207: Нет изображения на экране | D10: Преподаватель: Иванов А.А. Подразделение: Кафедра органической химии Аудитория: Гл-207 Дата возникновения проблемы: 13.03.2024 10:23 Описание проблемы: Нет изображения на экране Предпринятые действия: Проверил настройки ПО, проблема не решена Контактный телефон: +7 (971) 467-74-18 | E10: Решена | F10: Highest | G10: Решено | H10: 45933.536 | I10: 45935.182 | J10: 45935.182 | K10: Сетевое оборудование | L10: MMC v2.4 | M10: MMC v2.4 | N10: Иванов А.А. | O10: Сидоров Д.К. | P10: 0 | T10: 5h | U10: 311 | V10: Гл-207 | W10: B | X10: Нет изображения на экране | Y10: Кафедра органической химии | Z10: Высокое | AA10: Телефон | AB10: 39.5 | AC10: Требуется замена блока питания. Оборудование снято с эксплуатации. | AD10: training_needed | AE10: Windows 11 / AMD CPU | AG10: 45933.536 | AH10: 45935.182 | AJ10: 2 | AK10: Низкая | AL10: На месте
A11: MMC-1037 | B11: Запрос на обслуживание | C11: Неисправность оборудования в Гл-112: Не могу включить проектор | D11: Преподаватель: Федоров Б.Б. Подразделение: Кафедра общей физики Аудитория: Гл-112 Дата возникновения проблемы: 12.03.2024 15:51 Описание проблемы: Не могу включить проектор Предпринятые действия: Попытался использовать запасные кабели, проблема сохраняется Контактный телефон: +7 (913) 237-05-89 | E11: Решена | F11: Medium | G11: Решено | H11: 45933.69 | I11: 45934.561 | J11: 45934.561 | K11: Другое оборудование | L11: MMC v3.7 | M11: MMC v4.6 | N11: Федоров Б.Б. | O11: Петрова М.В. | P11: 1 | Q11: support_team | T11: 4h | U11: 338 | V11: Гл-112 | W11: A | X11: Не могу включить проектор | Y11: Кафедра общей физики | Z11: Среднее | AA11: Email | AB11: 20.9 | AC11: Требуется замена блока питания. Оборудование снято с эксплуатации. | AD11: software | AE11: Windows 11 / Intel CPU | AG11: 45933.69 | AH11: 45934.561 | AJ11: 0 | AK11: Низкая | AL11: Консультация
A12: MMC-1001 | B12: Инцидент | C12: Неисправность оборудования в Гл-111: Не запускается мультимедийное ПО | D12: СООБЩЕНИЕ О ПРОБЛЕМЕ ------------------ Аудитория: Гл-111 Оборудование: Мультимедийный комплекс Преподаватель: Федоров А.А. Кафедра: Кафедра истории России ПРОБЛЕМА: Не запускается мультимедийное ПО ВРЕМЯ ВОЗНИКНОВЕНИЯ: 07.03.2024 18:44 ДОПОЛНИТЕЛЬНАЯ ИНФОРМАЦИЯ: Иногда работает нормально, иногда нет СТАТУС: Требуется вмешательство специалиста | E12: Решена | F12: Low | G12: Решено | H12: 45934.366 | I12: 45934.997 | J12: 45934.997 | K12: Проектор | L12: MMC v1.6 | M12: MMC v3.4 | N12: Федоров А.А. | P12: 2 | T12: 1h | U12: 283 | V12: Гл-111 | W12: A | X12: Не запускается мультимедийное ПО | Y12: Кафедра истории России | Z12: Среднее | AA12: Портал самообслуживания | AB12: 15.1 | AC12: Проблема решена удаленно через систему управления. | AD12: hardware | AE12: Windows 7 / AMD CPU | AG12: 45934.366 | AH12: 45934.997 | AJ12: 2 | AK12: Высокая | AL12: Удаленно
A13: MMC-1088 | B13: Проблема | C13: Не могу включить проектор. Аудитория: Гл-202 | D13: Преподаватель: Федоров А.А. Подразделение: Кафедра органической химии Аудитория: Гл-202 Дата возникновения проблемы: 03.03.2024 09:03 Описание проблемы: Не могу включить проектор Предпринятые действия: Попытался использовать запасные кабели, проблема сохраняется Контактный телефон: +7 (938) 612-07-50 | E13: Решена | F13: Low | G13: Решено | H13: 45934.451 | I13: 45934.52 | J13: 45934.52 | K13: Сетевое оборудование | L13: MMC v2.7 | M13: MMC v4.6 | N13: Федоров А.А. | P13: 3 | Q13: multimedia_dept | T13: 1h | U13: 428 | V13: Гл-202 | W13: B | X13: Не могу включить проектор | Y13: Кафедра органической химии | Z13: Критичное | AA13: Телефон | AB13: 1.7 | AC13: Требуется настройка проектора. Выполнена калибровка. | AD13: urgent | AE13: Windows 11 / Intel CPU | AG13: 45934.451 | AH13: 45934.52 | AI13: 45939 | AJ13: 0 | AK13: Средняя | AL13: На месте
A14: MMC-1062 | B14: Запрос на обслуживание | C14: Проблема: Проблема с переключением режимов (аудитория Гл-207) | D14: СООБЩЕНИЕ О ПРОБЛЕМЕ ------------------ Аудитория: Гл-207 Оборудование: Мультимедийный комплекс Преподаватель: Иванов А.А. Кафедра: Кафедра иностранных языков ПРОБЛЕМА: Проблема с переключением режимов ВРЕМЯ ВОЗНИКНОВЕНИЯ: 03.03.2024 08:16 ДОПОЛНИТЕЛЬНАЯ ИНФОРМАЦИЯ: Проблема возникает при каждом использовании СТАТУС: Требуется вмешательство специалиста | E14: Решена | F14: Medium | G14: Решено | H14: 45934.48 | I14: 45934.711 | J14: 45934.711 | K14: Другое оборудование | L14: MMC v3.8 | M14: MMC v4.6 | N14: Иванов А.А. | O14: Петрова М.В. | P14: 1 | Q14: support_team | T14: 1h | U14: 361 | V14: Гл-207 | W14: B | X14: Проблема с переключением режимов | Y14: Кафедра иностранных языков | Z14: Высокое | AA14: Email | AB14: 5.5 | AC14: Проведена диагностика. Оборудование работает в штатном режиме. | AD14: hardware | AE14: Windows 7 / AMD CPU | AG14: 45934.48 | AH14: 45934.711 | AI14: 45941 | AJ14: 1 | AK14: Низкая | AL14: Удаленно
A15: MMC-1083 | B15: Инцидент | C15: Не подключается ноутбук через HDMI в аудитории Гл-206 | D15: ЗАЯВКА В ТЕХПОДДЕРЖКУ 1. Общие сведения: - Аудитория: Гл-206 - Преподаватель: Смирнов В.В. - Подразделение: Кафедра истории России - Дата/время: 27.03.2024 11:54 2. Суть проблемы: Не подключается ноутбук через HDMI 3. Симптомы: Посторонние шумы в акустике 4. Влияние на учебный процесс: Перенесено в другую аудиторию Контакт для обратной связи: Смирнов В.В. | E15: Решена | F15: Medium | G15: Решено | H15: 45934.658 | I15: 45934.967 | J15: 45934.967 | K15: Проектор | L15: MMC v1.3 | M15: MMC v1.5 | N15: Смирнов В.В. | P15: 2 | Q15: multimedia_dept | T15: 6h | U15: 154 | V15: Гл-206 | W15: B | X15: Не подключается ноутбук через HDMI | Y15: Кафедра истории России | Z15: Критичное | AA15: Email | AB15: 7.4 | AD15: software | AE15: Windows 10 / Intel CPU | AG15: 45934.658 | AH15: 45934.967 | AJ15: 0 | AK15: Средняя | AL15: Удаленно
A16: MMC-1068 | B16: Инцидент | C16: Сложность с настройкой источников. Аудитория: Гл-207 | D16: ЗАЯВКА В ТЕХПОДДЕРЖКУ 1. Общие сведения: - Аудитория: Гл-207 - Преподаватель: Морозов Б.Б. - Подразделение: Кафедра истории России - Дата/время: 09.03.2024 10:01 2. Суть проблемы: Сложность с настройкой источников 3. Симптомы: Оборудование не реагирует на команды 4. Влияние на учебный процесс: Перенесено в другую аудиторию Контакт для обратной связи: Морозов Б.Б. | E16: Решена | F16: High | G16: Решено | H16: 45935.592 | I16: 45937.019 | J16: 45937.019 | K16: Сетевое оборудование | L16: MMC v3.5 | M16: MMC v2.2 | N16: Морозов Б.Б. | P16: 1 | Q16: support_team | T16: 6h | U16: 128 | V16: Гл-207 | W16: B | X16: Сложность с настройкой источников | Y16: Кафедра истории России | Z16: Высокое | AA16: Личное обращение | AB16: 34.2 | AD16: equipment | AE16: Windows 8 / Intel CPU | AG16: 45935.592 | AH16: 45937.019 | AI16: 45941 | AJ16: 2 | AK16: Высокая | AL16: Удаленно
A17: MMC-1082 | B17: Инцидент | C17: Неисправность оборудования в Гл-215: Не могу включить проектор | D17: ЗАЯВКА В ТЕХПОДДЕРЖКУ 1. Общие сведения: - Аудитория: Гл-215 - Преподаватель: Сидоров В.В. - Подразделение: Кафедра иностранных языков - Дата/время: 22.03.2024 11:30 2. Суть проблемы: Не могу включить проектор 3. Симптомы: Изображение/звук появляются и пропадают 4. Влияние на учебный процесс: Занятие отменено Контакт для обратной связи: Сидоров В.В. | E17: Решена | F17: Highest | G17: Решено | H17: 45935.665 | I17: 45936.81 | J17: 45936.81 | K17: Акустика | L17: MMC v3.7 | M17: MMC v4.2 | N17: Сидоров В.В. | P17: 3 | Q17: support_team | T17: 3h | U17: 125 | V17: Гл-215 | W17: B | X17: Не могу включить проектор | Y17: Кафедра иностранных языков | Z17: Высокое | AA17: Личное обращение | AB17: 27.5 | AD17: equipment | AE17: Windows 7 / AMD CPU | AG17: 45935.665 | AH17: 45936.81 | AJ17: 0 | AK17: Средняя | AL17: На месте
A18: MMC-1093 | B18: Инцидент | C18: Проблема: Не могу включить проектор (аудитория Гл-201) | D18: СООБЩЕНИЕ О ПРОБЛЕМЕ ------------------ Аудитория: Гл-201 Оборудование: Мультимедийный комплекс Преподаватель: Попов А.А. Кафедра: Кафедра общей физики ПРОБЛЕМА: Не могу включить проектор ВРЕМЯ ВОЗНИКНОВЕНИЯ: 15.03.2024 17:30 ДОПОЛНИТЕЛЬНАЯ ИНФОРМАЦИЯ: Иногда работает нормально, иногда нет СТАТУС: Требуется вмешательство специалиста | E18: В работе | F18: Medium | H18: 45935.734 | I18: 45938.484 | K18: ПО | L18: MMC v1.9 | N18: Попов А.А. | O18: Васильев И.Н. | P18: 1 | Q18: multimedia_dept | V18: Гл-201 | W18: B | X18: Не могу включить проектор | Y18: Кафедра общей физики | Z18: Низкое | AA18: Телефон | AD18: training_needed | AE18: Windows 8 / Intel CPU | AG18: 45935.734 | AJ18: 3 | AK18: Низкая | AL18: Консультация
A19: MMC-1060 | B19: Инцидент | C19: Не подключается ноутбук через HDMI. Аудитория: Гл-110 | D19: Преподаватель: Иванов Б.Б. Подразделение: Кафедра информатики и вычислительной техники Аудитория: Гл-110 Дата возникновения проблемы: 06.03.2024 12:05 Описание проблемы: Не подключается ноутбук через HDMI Предпринятые действия: Переключил источники сигнала, безрезультатно Контактный телефон: +7 (912) 770-63-24 | E19: Решена | F19: Medium | G19: Решено | H19: 45935.746 | I19: 45936.702 | J19: 45936.702 | K19: Другое оборудование | L19: MMC v1.0 | M19: MMC v4.4 | N19: Иванов Б.Б. | O19: Кузнецова Е.П. | P19: 3 | Q19: multimedia_dept | T19: 1h | U19: 100 | V19: Гл-110 | W19: A | X19: Не подключается ноутбук через HDMI | Y19: Кафедра информатики и вычислительной техники | Z19: Высокое | AA19: Личное обращение | AB19: 22.9 | AD19: hardware | AE19: Windows 8 / AMD CPU | AG19: 45935.746 | AH19: 45936.702 | AI19: 45942 | AJ19: 0 | AK19: Средняя | AL19: Консультация
A20: MMC-1100 | B20: Запрос на обслуживание | C20: Аудитория Гл-212: Сложность с настройкой источников | D20: СООБЩЕНИЕ О ПРОБЛЕМЕ ------------------ Аудитория: Гл-212 Оборудование: Мультимедийный комплекс Преподаватель: Васильев В.В. Кафедра: Кафедра иностранных языков ПРОБЛЕМА: Сложность с настройкой источников ВРЕМЯ ВОЗНИКНОВЕНИЯ: 07.03.2024 17:36 ДОПОЛНИТЕЛЬНАЯ ИНФОРМАЦИЯ: Проблема появилась после обновления ПО СТАТУС: Требуется вмешательство специалиста | E20: Закрыта | F20: Medium | G20: Решено | H20: 45936.342 | I20: 45937.671 | J20: 45937.671 | K20: Сетевое оборудование | L20: MMC v3.7 | M20: MMC v1.6 | N20: Васильев В.В. | O20: Федорова Т.С. | P20: 1 | T20: 3h | U20: 315 | V20: Гл-212 | W20: B | X20: Сложность с настройкой источников | Y20: Кафедра иностранных языков | Z20: Низкое | AA20: Телефон | AB20: 31.9 | AD20: urgent | AE20: Windows 8 / AMD CPU | AG20: 45936.342 | AH20: 45937.671 | AJ20: 2 | AK20: Высокая | AL20: Консультация
A21: MMC-1032 | B21: Инцидент | C21: Другая проблема. Аудитория: Гл-103 | D21: СООБЩЕНИЕ О ПРОБЛЕМЕ ------------------ Аудитория: Гл-103 Оборудование: Мультимедийный комплекс Преподаватель: Федоров В.В. Кафедра: Кафедра философии и социологии ПРОБЛЕМА: Другая проблема ВРЕМЯ ВОЗНИКНОВЕНИЯ: 26.03.2024 15:57 ДОПОЛНИТЕЛЬНАЯ ИНФОРМАЦИЯ: Проблема появилась после обновления ПО СТАТУС: Требуется вмешательство специалиста | E21: Решена | F21: Medium | G21: Решено | H21: 45936.453 | I21: 45938.156 | J21: 45938.156 | K21: Сетевое оборудование | L21: MMC v3.8 | M21: MMC v4.2 | N21: Федоров В.В. | O21: Сидоров Д.К. | P21: 2 | T21: 3h | U21: 383 | V21: Гл-103 | W21: A | X21: Другая проблема | Y21: Кафедра философии и социологии | Z21: Критичное | AA21: Телефон | AB21: 40.9 | AD21: equipment | AE21: Windows 9 / AMD CPU | AF21: MMC-0918 | AG21: 45936.453 | AH21: 45938.156 | AI21: 45937 | AJ21: 1 | AK21: Средняя | AL21: На месте
A22: MMC-1094 | B22: Инцидент | C22: Сложность с настройкой источников. Аудитория: Гл-202 | D22: ЗАЯВКА В ТЕХПОДДЕРЖКУ 1. Общие сведения: - Аудитория: Гл-202 - Преподаватель: Смирнов Б.Б. - Подразделение: Кафедра высшей математики - Дата/время: 23.03.2024 16:27 2. Суть проблемы: Сложность с настройкой источников 3. Симптомы: Посторонние шумы в акустике 4. Влияние на учебный процесс: Перенесено в другую аудиторию Контакт для обратной связи: Смирнов Б.Б. | E22: Решена | F22: Medium | G22: Решено | H22: 45936.665 | I22: 45936.828 | J22: 45936.828 | K22: Другое оборудование | L22: MMC v3.9 | M22: MMC v1.6 | N22: Смирнов Б.Б. | P22: 3 | R22: 1h | T22: 3h | U22: 406 | V22: Гл-202 | W22: B | X22: Сложность с настройкой источников | Y22: Кафедра высшей математики | Z22: Низкое | AA22: Портал самообслуживания | AB22: 3.9 | AD22: software | AE22: Windows 7 / Intel CPU | AG22: 45936.665 | AH22: 45936.828 | AJ22: 1 | AK22: Высокая | AL22: На месте
A23: MMC-1047 | B23: Инцидент | C23: Проблема: Не запускается мультимедийное ПО (аудитория Гл-105) | D23: Преподаватель: Волков Б.Б. Подразделение: Кафедра информатики и вычислительной техники Аудитория: Гл-105 Дата возникновения проблемы: 15.03.2024 11:34 Описание проблемы: Не запускается мультимедийное ПО Предпринятые действия: Попытался использовать запасные кабели, проблема сохраняется Контактный телефон: +7 (919) 079-03-06 | E23: Закрыта | F23: Medium | G23: Решено | H23: 45937.376 | I23: 45938.528 | J23: 45938.528 | K23: Другое оборудование | L23: MMC v3.5 | M23: MMC v3.3 | N23: Волков Б.Б. | P23: 1 | Q23: multimedia_dept | T23: 4h | U23: 253 | V23: Гл-105 | W23: A | X23: Не запускается мультимедийное ПО | Y23: Кафедра информатики и вычислительной техники | Z23: Среднее | AA23: Телефон | AB23: 27.6 | AC23: Настроены параметры отображения. Проблема устранена. | AD23: software | AE23: Windows 8 / AMD CPU | AG23: 45937.376 | AH23: 45938.528 | AJ23: 2 | AK23: Высокая | AL23: Консультация
A24: MMC-1009 | B24: Запрос на обслуживание | C24: Аудитория Гл-104: Не могу включить проектор | D24: Преподаватель: Сидоров А.А. Подразделение: Кафедра экономики и менеджмента Аудитория: Гл-104 Дата возникновения проблемы: 06.03.2024 17:16 Описание проблемы: Не могу включить проектор Предпринятые действия: Проверил подключение питания, перезагрузил оборудование Контактный телефон: +7 (945) 868-50-14 | E24: Решена | F24: Medium | G24: Решено | H24: 45937.64 | I24: 45938.275 | J24: 45938.275 | K24: Компьютер | L24: MMC v2.9 | M24: MMC v1.6 | N24: Сидоров А.А. | O24: Кузнецова Е.П. | P24: 2 | R24: 1h | T24: 5h | U24: 375 | V24: Гл-104 | W24: A | X24: Не могу включить проектор | Y24: Кафедра экономики и менеджмента | Z24: Высокое | AA24: Портал самообслуживания | AB24: 15.2 | AD24: software | AE24: Windows 9 / AMD CPU | AG24: 45937.64 | AH24: 45938.275 | AJ24: 2 | AK24: Высокая | AL24: На месте
A25: MMC-1080 | B25: Запрос на обслуживание | C25: Неисправность оборудования в Гл-203: Сложность с настройкой источников | D25: ЗАЯВКА В ТЕХПОДДЕРЖКУ 1. Общие сведения: - Аудитория: Гл-203 - Преподаватель: Федоров А.А. - Подразделение: Кафедра истории России - Дата/время: 16.03.2024 11:38 2. Суть проблемы: Сложность с настройкой источников 3. Симптомы: Изображение/звук появляются и пропадают 4. Влияние на учебный процесс: Перенесено в другую аудиторию Контакт для обратной связи: Федоров А.А. | E25: Открыта | F25: Medium | H25: 45937.778 | I25: 45940.028 | K25: Компьютер | L25: MMC v1.0 | N25: Федоров А.А. | O25: Кузнецова Е.П. | P25: 3 | Q25: support_team | V25: Гл-203 | W25: B | X25: Сложность с настройкой источников | Y25: Кафедра истории России | Z25: Критичное | AA25: Телефон | AC25: Настроены параметры отображения. Проблема устранена. | AD25: software | AE25: Windows 10 / Intel CPU | AF25: MMC-0999 | AG25: 45937.778 | AJ25: 0 | AK25: Средняя | AL25: Консультация
A26: MMC-1016 | B26: Проблема | C26: Аудитория Гл-105: Не могу включить проектор | D26: ЗАЯВКА В ТЕХПОДДЕРЖКУ 1. Общие сведения: - Аудитория: Гл-105 - Преподаватель: Иванов Б.Б. - Подразделение: Кафедра информатики и вычислительной техники - Дата/время: 11.03.2024 10:03 2. Суть проблемы: Не могу включить проектор 3. Симптомы: Оборудование не реагирует на команды 4. Влияние на учебный процесс: Занятие отменено Контакт для обратной связи: Иванов Б.Б. | E26: Решена | F26: Medium | G26: Решено | H26: 45938.549 | I26: 45940.49 | J26: 45940.49 | K26: Проектор | L26: MMC v3.0 | M26: MMC v2.2 | N26: Иванов Б.Б. | O26: Васильев И.Н. | P26: 0 | T26: 4h | U26: 410 | V26: Гл-105 | W26: A | X26: Не могу включить проектор | Y26: Кафедра информатики и вычислительной техники | Z26: Высокое | AA26: Личное обращение | AB26: 46.6 | AD26: training_needed | AE26: Windows 9 / AMD CPU | AG26: 45938.549 | AH26: 45940.49 | AI26: 45943 | AJ26: 0 | AK26: Низкая | AL26: Консультация
A27: MMC-1026 | B27: Запрос на обслуживание | C27: Аудитория Гл-115: Не запускается мультимедийное ПО | D27: СООБЩЕНИЕ О ПРОБЛЕМЕ ------------------ Аудитория: Гл-115 Оборудование: Мультимедийный комплекс Преподаватель: Кузнецов Б.Б. Кафедра: Кафедра экономики и менеджмента ПРОБЛЕМА: Не запускается мультимедийное ПО ВРЕМЯ ВОЗНИКНОВЕНИЯ: 26.03.2024 10:35 ДОПОЛНИТЕЛЬНАЯ ИНФОРМАЦИЯ: Проблема появилась после обновления ПО СТАТУС: Требуется вмешательство специалиста | E27: Закрыта | F27: Medium | G27: Решено | H27: 45938.598 | I27: 45939.699 | J27: 45939.699 | K27: Другое оборудование | L27: MMC v2.0 | M27: MMC v3.9 | N27: Кузнецов Б.Б. | P27: 0 | Q27: multimedia_dept | T27: 2h | U27: 436 | V27: Гл-115 | W27: A | X27: Не запускается мультимедийное ПО | Y27: Кафедра экономики и менеджмента | Z27: Низкое | AA27: Email | AB27: 26.4 | AC27: Временное решение применено. Заказана запасная часть. | AD27: hardware | AE27: Windows 9 / Intel CPU | AG27: 45938.598 | AH27: 45939.699 | AJ27: 3 | AK27: Высокая | AL27: Консультация
A28: MMC-1003 | B28: Инцидент | C28: Проблема: Требуется инструкция по использованию (аудитория Гл-103) | D28: ЗАЯВКА В ТЕХПОДДЕРЖКУ 1. Общие сведения: - Аудитория: Гл-103 - Преподаватель: Васильев А.А. - Подразделение: Кафедра иностранных языков - Дата/время: 13.03.2024 14:38 2. Суть проблемы: Требуется инструкция по использованию 3. Симптомы: Оборудование не реагирует на команды 4. Влияние на учебный процесс: Занятие отменено Контакт для обратной связи: Васильев А.А. | E28: Решена | F28: Medium | G28: Решено | H28: 45938.69 | I28: 45940.292 | J28: 45940.292 | K28: ПО | L28: MMC v2.5 | M28: MMC v1.4 | N28: Васильев А.А. | O28: Федорова Т.С. | P28: 0 | Q28: multimedia_dept | R28: 3h | T28: 5h | U28: 490 | V28: Гл-103 | W28: A | X28: Требуется инструкция по использованию | Y28: Кафедра иностранных языков | Z28: Высокое | AA28: Телефон | AB28: 38.5 | AC28: Выявлена аппаратная неисправность. Запланирован ремонт. | AD28: software | AE28: Windows 11 / Intel CPU | AG28: 45938.69 | AH28: 45940.292 | AI28: 45943 | AJ28: 0 | AK28: Высокая | AL28: На месте
A29: MMC-1049 | B29: Запрос на обслуживание | C29: Нет звука в аудиосистеме. Аудитория: Гл-115 | D29: ЗАЯВКА В ТЕХПОДДЕРЖКУ 1. Общие сведения: - Аудитория: Гл-115 - Преподаватель: Морозов А.А. - Подразделение: Кафедра инженерной графики - Дата/время: 25.03.2024 13:58 2. Суть проблемы: Нет звука в аудиосистеме 3. Симптомы: Система зависает при определенных действиях 4. Влияние на учебный процесс: Проведено с ограничениями Контакт для обратной связи: Морозов А.А. | E29: В работе | F29: Highest | H29: 45938.74 | I29: 45940.031 | K29: Акустика | L29: MMC v3.2 | N29: Морозов А.А. | P29: 3 | Q29: support_team | V29: Гл-115 | W29: A | X29: Нет звука в аудиосистеме | Y29: Кафедра инженерной графики | Z29: Среднее | AA29: Email | AD29: equipment | AE29: Windows 10 / AMD CPU | AG29: 45938.74 | AI29: 45944 | AJ29: 3 | AK29: Средняя | AL29: Удаленно
A30: MMC-1024 | B30: Инцидент | C30: Аудитория Гл-107: Другая проблема | D30: ЗАЯВКА В ТЕХПОДДЕРЖКУ 1. Общие сведения: - Аудитория: Гл-107 - Преподаватель: Волков А.А. - Подразделение: Кафедра иностранных языков - Дата/время: 21.03.2024 18:38 2. Суть проблемы: Другая проблема 3. Симптомы: Система зависает при определенных действиях 4. Влияние на учебный процесс: Занятие проведено без мультимедийного оборудования Контакт для обратной связи: Волков А.А. | E30: Решена | F30: Low | G30: Решено | H30: 45939.364 | I30: 45940.592 | J30: 45940.592 | K30: ПО | L30: MMC v1.1 | M30: MMC v2.9 | N30: Волков А.А. | P30: 1 | Q30: support_team | R30: 1h | T30: 3h | U30: 174 | V30: Гл-107 | W30: A | X30: Другая проблема | Y30: Кафедра иностранных языков | Z30: Высокое | AA30: Портал самообслуживания | AB30: 29.5 | AC30: Требуется настройка проектора. Выполнена калибровка. | AD30: software | AE30: Windows 7 / Intel CPU | AG30: 45939.364 | AH30: 45940.592 | AI30: 45941 | AJ30: 2 | AK30: Низкая | AL30: Удаленно
A31: MMC-1017 | B31: Запрос на обслуживание | C31: Нет звука в аудиосистеме. Аудитория: Гл-104 | D31: ЗАЯВКА В ТЕХПОДДЕРЖКУ 1. Общие сведения: - Аудитория: Гл-104 - Преподаватель: Петров В.В. - Подразделение: Кафедра информатики и вычислительной техники - Дата/время: 22.03.2024 11:59 2. Суть проблемы: Нет звука в аудиосистеме 3. Симптомы: Посторонние шумы в акустике 4. Влияние на учебный процесс: Занятие отменено Контакт для обратной связи: Петров В.В. | E31: В работе | F31: Medium | H31: 45939.753 | I31: 45940.712 | K31: Другое оборудование | L31: MMC v1.4 | N31: Петров В.В. | O31: Петрова М.В. | P31: 0 | R31: 3h | V31: Гл-104 | W31: A | X31: Нет звука в аудиосистеме | Y31: Кафедра информатики и вычислительной техники | Z31: Низкое | AA31: Телефон | AD31: urgent | AE31: Windows 10 / AMD CPU | AG31: 45939.753 | AJ31: 0 | AK31: Высокая | AL31: Удаленно
A32: MMC-1005 | B32: Проблема | C32: Не запускается мультимедийное ПО. Аудитория: Гл-104 | D32: Преподаватель: Волков Б.Б. Подразделение: Кафедра безопасности информационных систем Аудитория: Гл-104 Дата возникновения проблемы: 15.03.2024 08:43 Описание проблемы: Не запускается мультимедийное ПО Предпринятые действия: Проверил подключение питания, перезагрузил оборудование Контактный телефон: +7 (976) 311-65-66 | E32: В работе | F32: Low | H32: 45939.772 | I32: 45940.48 | K32: Проектор | L32: MMC v1.3 | N32: Волков Б.Б. | P32: 3 | V32: Гл-104 | W32: A | X32: Не запускается мультимедийное ПО | Y32: Кафедра безопасности информационных систем | Z32: Среднее | AA32: Личное обращение | AD32: multimedia | AE32: Windows 10 / Intel CPU | AG32: 45939.772 | AI32: 45946 | AJ32: 0 | AK32: Низкая | AL32: Удаленно
A33: MMC-1038 | B33: Инцидент | C33: Аудитория Гл-103: Нет изображения на экране | D33: Преподаватель: Смирнов Б.Б. Подразделение: Кафедра инженерной графики Аудитория: Гл-103 Дата возникновения проблемы: 19.03.2024 17:09 Описание проблемы: Нет изображения на экране Предпринятые действия: Попытался использовать запасные кабели, проблема сохраняется Контактный телефон: +7 (984) 249-81-82 | E33: Решена | F33: High | G33: Решено | H33: 45940.424 | I33: 45942.35 | J33: 45942.35 | K33: Другое оборудование | L33: MMC v3.4 | M33: MMC v2.9 | N33: Смирнов Б.Б. | O33: Иванов А.С. | P33: 3 | Q33: multimedia_dept | T33: 6h | U33: 254 | V33: Гл-103 | W33: A | X33: Нет изображения на экране | Y33: Кафедра инженерной графики | Z33: Низкое | AA33: Email | AB33: 46.2 | AC33: Проведена диагностика. Оборудование работает в штатном режиме. | AD33: urgent | AE33: Windows 10 / Intel CPU | AG33: 45940.424 | AH33: 45942.35 | AJ33: 3 | AK33: Средняя | AL33: На месте
A34: MMC-1078 | B34: Проблема | C34: Другая проблема. Аудитория: Гл-209 | D34: Преподаватель: Кузнецов Б.Б. Подразделение: Кафедра экономики и менеджмента Аудитория: Гл-209 Дата возникновения проблемы: 15.03.2024 12:13 Описание проблемы: Другая проблема Предпринятые действия: Попытался использовать запасные кабели, проблема сохраняется Контактный телефон: +7 (952) 175-25-00 | E34: Закрыта | F34: High | G34: Решено | H34: 45940.585 | I34: 45941.008 | J34: 45941.008 | K34: Сетевое оборудование | L34: MMC v3.6 | M34: MMC v4.6 | N34: Кузнецов Б.Б. | O34: Попов Р.М. | P34: 0 | T34: 6h | U34: 291 | V34: Гл-209 | W34: B | X34: Другая проблема | Y34: Кафедра экономики и менеджмента | Z34: Критичное | AA34: Портал самообслуживания | AB34: 10.1 | AC34: Требуется замена блока питания. Оборудование снято с эксплуатации. | AD34: equipment | AE34: Windows 7 / Intel CPU | AG34: 45940.585 | AH34: 45941.008 | AJ34: 2 | AK34: Средняя | AL34: Удаленно
A35: MMC-1030 | B35: Проблема | C35: Неисправность оборудования в Гл-102: Требуется инструкция по использованию | D35: ЗАЯВКА В ТЕХПОДДЕРЖКУ 1. Общие сведения: - Аудитория: Гл-102 - Преподаватель: Иванов В.В. - Подразделение: Кафедра высшей математики - Дата/время: 20.03.2024 15:32 2. Суть проблемы: Требуется инструкция по использованию 3. Симптомы: Посторонние шумы в акустике 4. Влияние на учебный процесс: Занятие отменено Контакт для обратной связи: Иванов В.В. | E35: Открыта | F35: Low | H35: 45940.644 | I35: 45942.644 | K35: Компьютер | L35: MMC v3.1 | N35: Иванов В.В. | O35: Сидоров Д.К. | P35: 0 | R35: 4h | V35: Гл-102 | W35: A | X35: Требуется инструкция по использованию | Y35: Кафедра высшей математики | Z35: Высокое | AA35: Портал самообслуживания | AD35: urgent | AE35: Windows 10 / AMD CPU | AG35: 45940.644 | AI35: 45941 | AJ35: 2 | AK35: Низкая | AL35: На месте
A36: MMC-1059 | B36: Запрос на обслуживание | C36: Не подключается ноутбук через HDMI в аудитории Гл-103 | D36: СООБЩЕНИЕ О ПРОБЛЕМЕ ------------------ Аудитория: Гл-103 Оборудование: Мультимедийный комплекс Преподаватель: Петров А.А. Кафедра: Кафедра общей физики ПРОБЛЕМА: Не подключается ноутбук через HDMI ВРЕМЯ ВОЗНИКНОВЕНИЯ: 19.03.2024 18:17 ДОПОЛНИТЕЛЬНАЯ ИНФОРМАЦИЯ: Ранее подобных проблем не наблюдалось СТАТУС: Требуется вмешательство специалиста | E36: Решена | F36: Medium | G36: Решено | H36: 45941.512 | I36: 45942.927 | J36: 45942.927 | K36: Проектор | L36: MMC v2.8 | M36: MMC v3.5 | N36: Петров А.А. | O36: Федорова Т.С. | P36: 2 | Q36: multimedia_dept | T36: 6h | U36: 147 | V36: Гл-103 | W36: A | X36: Не подключается ноутбук через HDMI | Y36: Кафедра общей физики | Z36: Низкое | AA36: Портал самообслуживания | AB36: 34.0 | AC36: Требуется замена блока питания. Оборудование снято с эксплуатации. | AD36: training_needed | AE36: Windows 8 / AMD CPU | AF36: MMC-0963 | AG36: 45941.512 | AH36: 45942.927 | AJ36: 2 | AK36: Средняя | AL36: Консультация
A37: MMC-1039 | B37: Запрос на обслуживание | C37: Проблема: Не запускается мультимедийное ПО (аудитория Гл-104) | D37: СООБЩЕНИЕ О ПРОБЛЕМЕ ------------------ Аудитория: Гл-104 Оборудование: Мультимедийный комплекс Преподаватель: Волков А.А. Кафедра: Кафедра иностранных языков ПРОБЛЕМА: Не запускается мультимедийное ПО ВРЕМЯ ВОЗНИКНОВЕНИЯ: 08.03.2024 10:06 ДОПОЛНИТЕЛЬНАЯ ИНФОРМАЦИЯ: Проблема появилась после обновления ПО СТАТУС: Требуется вмешательство специалиста | E37: Решена | F37: Medium | G37: Решено | H37: 45941.715 | I37: 45943.645 | J37: 45943.645 | K37: Акустика | L37: MMC v2.9 | M37: MMC v3.3 | N37: Волков А.А. | O37: Федорова Т.С. | P37: 3 | Q37: support_team | R37: 4h | T37: 1h | U37: 146 | V37: Гл-104 | W37: A | X37: Не запускается мультимедийное ПО | Y37: Кафедра иностранных языков | Z37: Низкое | AA37: Личное обращение | AB37: 46.3 | AC37: Оборудование исправно. Проведен инструктаж пользователя. | AD37: hardware | AE37: Windows 9 / Intel CPU | AG37: 45941.715 | AH37: 45943.645 | AJ37: 3 | AK37: Средняя | AL37: Консультация
A38: MMC-1042 | B38: Проблема | C38: Аудитория Гл-109: Нет звука в аудиосистеме | D38: ЗАЯВКА В ТЕХПОДДЕРЖКУ 1. Общие сведения: - Аудитория: Гл-109 - Преподаватель: Смирнов В.В. - Подразделение: Кафедра иностранных языков - Дата/время: 10.03.2024 12:45 2. Суть проблемы: Нет звука в аудиосистеме 3. Симптомы: Система зависает при определенных действиях 4. Влияние на учебный процесс: Проведено с ограничениями Контакт для обратной связи: Смирнов В.В. | E38: Решена | F38: Medium | G38: Решено | H38: 45941.771 | I38: 45942.653 | J38: 45942.653 | K38: Другое оборудование | L38: MMC v2.4 | M38: MMC v1.9 | N38: Смирнов В.В. | O38: Попов Р.М. | P38: 3 | Q38: support_team | R38: 2h | T38: 3h | U38: 121 | V38: Гл-109 | W38: A | X38: Нет звука в аудиосистеме | Y38: Кафедра иностранных языков | Z38: Среднее | AA38: Телефон | AB38: 21.2 | AD38: training_needed | AE38: Windows 9 / AMD CPU | AG38: 45941.771 | AH38: 45942.653 | AI38: 45944 | AJ38: 2 | AK38: Низкая | AL38: Удаленно
A39: MMC-1095 | B39: Проблема | C39: Аудитория Гл-207: Нет звука в аудиосистеме | D39: ЗАЯВКА В ТЕХПОДДЕРЖКУ 1. Общие сведения: - Аудитория: Гл-207 - Преподаватель: Смирнов В.В. - Подразделение: Кафедра экономики и менеджмента - Дата/время: 18.03.2024 16:30 2. Суть проблемы: Нет звука в аудиосистеме 3. Симптомы: Система зависает при определенных действиях 4. Влияние на учебный процесс: Проведено с ограничениями Контакт для обратной связи: Смирнов В.В. | E39: Решена | F39: Medium | G39: Решено | H39: 45942.381 | I39: 45943.976 | J39: 45943.976 | K39: Другое оборудование | L39: MMC v1.3 | M39: MMC v4.2 | N39: Смирнов В.В. | P39: 3 | Q39: support_team | R39: 1h | T39: 2h | U39: 299 | V39: Гл-207 | W39: B | X39: Нет звука в аудиосистеме | Y39: Кафедра экономики и менеджмента | Z39: Критичное | AA39: Телефон | AB39: 38.3 | AC39: Проблема решена удаленно через систему управления. | AD39: hardware | AE39: Windows 10 / Intel CPU | AG39: 45942.381 | AH39: 45943.976 | AJ39: 0 | AK39: Высокая | AL39: Удаленно
A40: MMC-1087 | B40: Проблема | C40: Проблема: Другая проблема (аудитория Гл-209) | D40: СООБЩЕНИЕ О ПРОБЛЕМЕ ------------------ Аудитория: Гл-209 Оборудование: Мультимедийный комплекс Преподаватель: Смирнов Б.Б. Кафедра: Кафедра высшей математики ПРОБЛЕМА: Другая проблема ВРЕМЯ ВОЗНИКНОВЕНИЯ: 12.03.2024 12:13 ДОПОЛНИТЕЛЬНАЯ ИНФОРМАЦИЯ: Проблема возникает при каждом использовании СТАТУС: Требуется вмешательство специалиста | E40: Решена | F40: Medium | G40: Решено | H40: 45942.41 | I40: 45943.836 | J40: 45943.836 | K40: Другое оборудование | L40: MMC v3.9 | M40: MMC v2.0 | N40: Смирнов Б.Б. | O40: Смирнова О.Л. | P40: 3 | T40: 5h | U40: 470 | V40: Гл-209 | W40: B | X40: Другая проблема | Y40: Кафедра высшей математики | Z40: Среднее | AA40: Телефон | AB40: 34.2 | AC40: Временное решение применено. Заказана запасная часть. | AD40: hardware | AE40: Windows 11 / AMD CPU | AG40: 45942.41 | AH40: 45943.836 | AJ40: 1 | AK40: Средняя | AL40: Консультация
...

Sheet simple_data_Table
A1: Issue Key | B1: Summary | C1: Status | D1: Priority | E1: Created | F1: Аудитория | G1: Группа A/B теста | H1: Категория проблемы | I1: Component/s | J1: Время решения (часы) | K1: Кафедра | L1: Влияние на процесс
A2: MMC-1004 | B2: Не могу включить проектор в аудитории Гл-108 | C2: Решена | D2: Low | E2: 45931.416 | F2: Гл-108 | G2: A | H2: Не могу включить проектор | I2: Другое оборудование | J2: 20.2 | K2: Кафедра безопасности информационных систем | L2: Высокое
A3: MMC-1097 | B3: Неисправность оборудования в Гл-210: Не могу включить проектор | C3: Решена | D3: Medium | E3: 45931.508 | F3: Гл-210 | G3: B | H3: Не могу включить проектор | I3: Сетевое оборудование | J3: 7.6 | K3: Кафедра иностранных языков | L3: Низкое
A4: MMC-1033 | B4: Нет изображения на экране в аудитории Гл-115 | C4: Решена | D4: Low | E4: 45931.585 | F4: Гл-115 | G4: A | H4: Нет изображения на экране | I4: ПО | J4: 24.2 | K4: Кафедра иностранных языков | L4: Низкое
A5: MMC-1091 | B5: Неисправность оборудования в Гл-211: Другая проблема | C5: Решена | D5: Medium | E5: 45931.734 | F5: Гл-211 | G5: B | H5: Другая проблема | I5: Акустика | J5: 38.2 | K5: Кафедра инженерной графики | L5: Критичное
A6: MMC-1074 | B6: Аудитория Гл-208: Сложность с настройкой источников | C6: Решена | D6: Low | E6: 45932.428 | F6: Гл-208 | G6: B | H6: Сложность с настройкой источников | I6: Сетевое оборудование | J6: 40.6 | K6: Кафедра информатики и вычислительной техники | L6: Среднее
A7: MMC-1025 | B7: Неисправность оборудования в Гл-105: Не могу включить проектор | C7: Решена | D7: Medium | E7: 45932.449 | F7: Гл-105 | G7: A | H7: Не могу включить проектор | I7: Сетевое оборудование | J7: 8.8 | K7: Кафедра иностранных языков | L7: Среднее
A8: MMC-1035 | B8: Не подключается ноутбук через HDMI. Аудитория: Гл-105 | C8: Решена | D8: Medium | E8: 45932.758 | F8: Гл-105 | G8: A | H8: Не подключается ноутбук через HDMI | I8: Компьютер | J8: 4.9 | K8: Кафедра высшей математики | L8: Критичное
A9: MMC-1002 | B9: Другая проблема. Аудитория: Гл-112 | C9: В работе | D9: Medium | E9: 45933.363 | F9: Гл-112 | G9: A | H9: Другая проблема | I9: Другое оборудование | J9: 0 | K9: Кафедра органической химии | L9: Критичное
A10: MMC-1072 | B10: Аудитория Гл-207: Нет изображения на экране | C10: Решена | D10: Highest | E10: 45933.536 | F10: Гл-207 | G10: B | H10: Нет изображения на экране | I10: Сетевое оборудование | J10: 39.5 | K10: Кафедра органической химии | L10: Высокое
A11: MMC-1037 | B11: Неисправность оборудования в Гл-112: Не могу включить проектор | C11: Решена | D11: Medium | E11: 45933.69 | F11: Гл-112 | G11: A | H11: Не могу включить проектор | I11: Другое оборудование | J11: 20.9 | K11: Кафедра общей физики | L11: Среднее
A12: MMC-1001 | B12: Неисправность оборудования в Гл-111: Не запускается мультимедийное ПО | C12: Решена | D12: Low | E12: 45934.366 | F12: Гл-111 | G12: A | H12: Не запускается мультимедийное ПО | I12: Проектор | J12: 15.1 | K12: Кафедра истории России | L12: Среднее
A13: MMC-1088 | B13: Не могу включить проектор. Аудитория: Гл-202 | C13: Решена | D13: Low | E13: 45934.451 | F13: Гл-202 | G13: B | H13: Не могу включить проектор | I13: Сетевое оборудование | J13: 1.7 | K13: Кафедра органической химии | L13: Критичное
... A101: MMC-1063 | B101: Нет звука в аудиосистеме в аудитории Гл-202 | C101: Решена | D101: Low | E101: 45960.588 | F101: Гл-202 | G101: B | H101: Нет звука в аудиосистеме | I101: Компьютер | J101: 39 | K101: Кафедра общей физики | L101: Высокое

Sheet jira_aggregated_data
A1: Аудитория | B1: Группа A/B теста | C1: Количество заявок | D1: Среднее время решения
A2: Гл-101 | B2: A | C2: 3 | D2: 29.8
A3: Гл-102 | B3: A | C3: 7 | D3: 24.6
A4: Гл-103 | B4: A | C4: 7 | D4: 36.8
A5: Гл-104 | B5: A | C5: 6 | D5: 35.6
A6: Гл-105 | B6: A | C6: 5 | D6: 22.1
A7: Гл-106 | B7: A | C7: 3 | D7: 33.9
A8: Гл-107 | B8: A | C8: 3 | D8: 28.3
A9: Гл-108 | B9: A | C9: 2 | D9: 15
A10: Гл-109 | B10: A | C10: 6 | D10: 28.8
A11: Гл-110 | B11: A | C11: 4 | D11: 26.8
A12: Гл-111 | B12: A | C12: 4 | D12: 20.3
A13: Гл-112 | B13: A | C13: 3 | D13: 20.9
... A27: Гл-212 | B27: B | C27: 3 | D27: 29.6
A28: Гл-213 | B28: B | C28: 1 | D28: -
A29: Гл-215 | B29: B | C29: 5 | D29: 30.3

Sheet jira_daily_stats
A1: Дата | B1: A | C1: B
A2: 45931 | B2: 2 | C2: 2
A3: 45932 | B3: 2 | C3: 1
A4: 45933 | B4: 2 | C4: 1
A5: 45934 | B5: 1 | C5: 3
A6: 45935 | B6: 1 | C6: 3
A7: 45936 | B7: 1 | C7: 2
A8: 45937 | B8: 2 | C8: 1
A9: 45938 | B9: 4 | C9: 0
A10: 45939 | B10: 3 | C10: 0
A11: 45940 | B11: 2 | C11: 1
A12: 45941 | B12: 3 | C12: 0
A13: 45942 | B13: 2 | C13: 2
... A30: 45960 | B30: 1 | C30: 2

Sheet T-test
A1: Расчет T-теста
B2: Контрольная | C2: Тестовая
B3: {=_xlfn._xlws.FILTER(jira_aggregated_data[Количество заявок],jira_aggregated_data[Группа A/B теста]="A")} -> 3 | C3: {=_xlfn._xlws.FILTER(jira_aggregated_data[Количество заявок],jira_aggregated_data[Группа A/B теста]="B")} -> 4
B4: 7 | C4: 5
B5: 7 | C5: 3
B6: 6 | C6: 1
B7: 5 | C7: 1
B8: 3 | C8: 2
B9: 3 | C9: 5
B10: 2 | C10: 2
B11: 6 | C11: 2
B12: 4 | C12: 4
B13: 4 | C13: 2
B14: 3 | C14: 3
B15: 2 | C15: 1
B16: 5 | C16: 5
A17: Итого | B17: =SUM(_xlfn.ANCHORARRAY(B3)) -> 60 | C17: =SUM(_xlfn.ANCHORARRAY(C3)) -> 40
A18: Статистика
A19: Среднее A | B19: =AVERAGE(_xlfn.ANCHORARRAY(B3)) -> 4.2857143 | C19: Расчет степеней свободы
A20: Среднее B | B20: =AVERAGE(_xlfn.ANCHORARRAY(C3)) -> 2.8571429 | C20: Дисперсия распределений выборочных средних первой выборки | D20: =POWER(B22,2)/B24 -> 0.04981685
A21: Гипотеза (Разность предпологаемых средних) | B21: 0 | C21: Дисперсия распределений выборочных средних второй выборки | D21: =POWER(B23,2)/B25 -> 0.057142857
A22: Стандартное отклонение A | B22: =_xlfn.STDEV.S(_xlfn.ANCHORARRAY(B3)) -> 1.7288756 | C22: Степени свободы | D22: =POWER((D20+D21),2)/((POWER(D20,2)/(B24-1))+(POWER(D21,2)/(B25-1))) -> 90.949089
A23: Стандартное отклонение B | B23: =_xlfn.STDEV.S(_xlfn.ANCHORARRAY(C3)) -> 1.5118579 | C23: T-тест | D23: =((B19-B20)-B21)/B26 -> 4.3680928
A24: Размер первой выборки | B24: =B17 -> 60 | C24: p-значение | D24: =_xlfn.T.TEST(B3:B16,C3:C16,1,2) -> 0.013999833
A25: Размер второй выборки | B25: =C17 -> 40 | C25: Интерпритация | D25: {=IF(D24, "Статистически значимо (p < 0.05)", IF(ячейка_p < 0.1, "Тенденция (p < 0.1)", "Не значимо (p ≥ 0.1)"))} -> Статистически значимо (p < 0.05)
A26: Оценка стандартной ошибки разности средних | B26: =SQRT((POWER(B22,2)/B24)+(POWER(B23,2)/B25)) -> 0.32704695 | C26: Эффект | D26: =(B20-B19)/B19 -> -0.33333333
C27: Доверительный интервал | D27: =_xlfn.CONFIDENCE.T(0.05,B22,B17) -> 0.44661594

Sheet Сводные таблицы
A1: Priority | B1: (Все)
A3: Названия строк | B3: Количество по полю Issue Key | C3: Среднее по полю Время решения (часы)
A4: A | B4: 60 | C4: 18.133333
A5: B | B5: 40 | C5: 22.29
A6: Общий итог | B6: 100 | C6: 19.796
A10: Количество по полю Issue Key | B10: Названия столбцов
A11: Названия строк | B11: A | C11: B | D11: Общий итог
A12: Другая проблема | B12: 5 | C12: 9 | D12: 14
A13: Не запускается мультимедийное ПО | B13: 8 | C13: 2 | D13: 10
A14: Не могу включить проектор | B14: 19 | C14: 5 | D14: 24
A15: Не подключается ноутбук через HDMI | B15: 7 | C15: 3 | D15: 10
A16: Нет звука в аудиосистеме | B16: 8 | C16: 2 | D16: 10
A17: Нет изображения на экране | B17: 9 | C17: 6 | D17: 15
A18: Проблема с переключением режимов | C18: 2 | D18: 2
A19: Сложность с настройкой источников | C19: 9 | D19: 9
A20: Требуется инструкция по использованию | B20: 4 | C20: 2 | D20: 6
A21: Общий итог | B21: 60 | C21: 40 | D21: 100
A25: Количество по полю Issue Key | B25: Названия столбцов
A26: Названия строк | B26: A | C26: B | D26: Общий итог | F26: Метрика | G26: Группа A | H26: Группа B | I26: Изменение
A27: Другая проблема | B27: 5 | C27: 9 | D27: 14 | F27: Всего заявок | G27: =COUNTIF(jira_simple_export[Группа A/B теста], "A") -> 60 | H27: =COUNTIF(jira_simple_export[Группа A/B теста], "B") -> 40 | I27: =1-H27/G27 -> 0.33333333
A28: Не запускается мультимедийное ПО | B28: 8 | C28: 2 | D28: 10 | F28: Среднее время решения | G28: =AVERAGEIF(jira_simple_export[Группа A/B теста], "A", jira_simple_export[Время решения (часы)]) -> 18.133333 | H28: =AVERAGEIF(jira_simple_export[Группа A/B теста], "B", jira_simple_export[Время решения (часы)]) -> 22.29 | I28: =1-H28/G28 -> -0.22922794
A29: Не могу включить проектор | B29: 19 | C29: 5 | D29: 24 | F29: Критичных заявок | G29: =COUNTIFS(jira_simple_export[Группа A/B теста], "A", jira_simple_export[Priority], "Highest") -> 1 | H29: =COUNTIFS(jira_simple_export[Группа A/B теста], "B", jira_simple_export[Priority], "Highest") -> 3 | I29: =1-H29/G29 -> -2
A30: Не подключается ноутбук через HDMI | B30: 7 | C30: 3 | D30: 10
A31: Нет звука в аудиосистеме | B31: 8 | C31: 2 | D31: 10
A32: Нет изображения на экране | B32: 9 | C32: 6 | D32: 15
A33: Проблема с переключением режимов | C33: 2 | D33: 2
A34: Сложность с настройкой источников | C34: 9 | D34: 9
A35: Требуется инструкция по использованию | B35: 4 | C35: 2 | D35: 6
A36: Общий итог | B36: 60 | C36: 40 | D36: 100

Sheet Дашборд
A1: A/B-тест: Новая структура инструкции для мультимедийных комплексов в аудиториях
A2: Ключевые метрики
A3: Метрика | B3: Группа A (старая инструкция) | C3: Группа B (новая инструкция) | D3: Изменение
A4: Всего заявок | B4: ='T-test'!B17 -> 60 | C4: ='T-test'!C17 -> 40 | D4: =(B4-C4)/B4 -> 0.33333333
A5: Среднее заявок/ауд | B5: ='T-test'!B19 -> 4.2857143 | C5: ='T-test'!B20 -> 2.8571429 | D5: =(B5-C5)/B5 -> 0.33333333
A6: Среднее время решения | B6: ='Сводные таблицы'!G28 -> 18.133333 | C6: ='Сводные таблицы'!H28 -> 22.29 | D6: =(B6-C6)/B6 -> -0.22922794
A7: Критичные заявки | B7: ='Сводные таблицы'!G29 -> 1 | C7: ='Сводные таблицы'!H29 -> 3 | D7: =(B7-C7)/B7 -> -2
A8: Результат Т-теста
A9: P-значение | B9: ='T-test'!D24 -> 0.013999833
A10: Статистическая значимость | B10: =IF(B9<0.05, "Статистически значимо", "Статистически не значимо") -> Статистически значимо
A11: Эффект | B11: =TEXT('T-test'!$D$26,"0,0%") -> -33,3%
A12: Доверительный интервал 95% | B12: =TEXT('T-test'!$D$27,"0,00") -> 0,45
A13: Количество по полю Issue Key | B13: Названия столбцов | E13: Вывод: Новая инструкция статистически значимо снижает количество заявок на 33,3%.
A14: Названия строк | B14: A | C14: B | D14: Общий итог | E14: Рекомендации
A15: Другая проблема | B15: 5 | C15: 9 | D15: 14 | E15: Внедрить новую инструкцию в остальных аудиториях
A16: Не запускается мультимедийное ПО | B16: 8 | C16: 2 | D16: 10 | E16: Провести повторный тест через 3 месяца
A17: Не могу включить проектор | B17: 19 | C17: 5 | D17: 24 | E17: Проработать сценарий возникновения критичных проблем
A18: Не подключается ноутбук через HDMI | B18: 7 | C18: 3 | D18: 10
A19: Нет звука в аудиосистеме | B19: 8 | C19: 2 | D19: 10
A20: Нет изображения на экране | B20: 9 | C20: 6 | D20: 15
A21: Проблема с переключением режимов | C21: 2 | D21: 2
A22: Сложность с настройкой источников | C22: 9 | D22: 9
A23: Требуется инструкция по использованию | B23: 4 | C23: 2 | D23: 6
A24: Общий итог | B24: 60 | C24: 40 | D24: 100
